<?xml version="1.0" ?>
<!-- =================================================================================== -->
<!-- |    This document was autogenerated by xacro from bipanda_spherized.xacro        | -->
<!-- |    EDITING THIS FILE BY HAND IS NOT RECOMMENDED                                 | -->
<!-- =================================================================================== -->
<robot name="bipanda" path="assets/panda/panda.urdf">
	<link name="world"/>
	<joint name="left_mount" type="fixed">
		<parent link="world"/>
		<child link="left_panda_link0"/>
		<origin rpy="0 0 0" xyz="0 -0.2875 0"/>
	</joint>
	<link name="left_panda_link0">
		<inertial>
			<origin rpy="0 0 0" xyz="0 0 0.05"/>
			<mass value="2.9"/>
			<inertia ixx="0.1" ixy="0" ixz="0" iyy="0.1" iyz="0" izz="0.1"/>
		</inertial>
		<visual>
			<geometry>
				<mesh filename="meshes/collision/link0.obj"/>
			</geometry>
			<material name="panda_white">
				<color rgba="1. 1. 1. 1."/>
			</material>
		</visual>
		<collision>
			<geometry>
				<sphere radius="0.08"/>
			</geometry>
			<origin rpy="0 0 0" xyz="0.0 0.0 0.05"/>
		</collision>
	</link>
	<link name="left_panda_link1">
		<inertial>
			<origin rpy="0 0 0" xyz="0 -0.04 -0.05"/>
			<mass value="2.7"/>
			<inertia ixx="0.1" ixy="0" ixz="0" iyy="0.1" iyz="0" izz="0.1"/>
		</inertial>
		<visual>
			<geometry>
				<mesh filename="meshes/visual/link1.obj"/>
			</geometry>
			<material name="panda_white"/>
		</visual>
		<collision>
			<geometry>
				<sphere radius="0.06"/>
			</geometry>
			<origin rpy="0 0 0" xyz="0.0 -0.08 0.0"/>
		</collision>
		<collision>
			<geometry>
				<sphere radius="0.06"/>
			</geometry>
			<origin rpy="0 0 0" xyz="0.0 -0.03 0.0"/>
		</collision>
		<collision>
			<geometry>
				<sphere radius="0.06"/>
			</geometry>
			<origin rpy="0 0 0" xyz="0.0 0.0 -0.12"/>
		</collision>
		<collision>
			<geometry>
				<sphere radius="0.06"/>
			</geometry>
			<origin rpy="0 0 0" xyz="0.0 0.0 -0.17"/>
		</collision>
	</link>
	<link name="left_panda_link2">
		<inertial>
			<origin rpy="0 0 0" xyz="0 -0.04 0.06"/>
			<mass value="2.73"/>
			<inertia ixx="0.1" ixy="0" ixz="0" iyy="0.1" iyz="0" izz="0.1"/>
		</inertial>
		<visual>
			<geometry>
				<mesh filename="meshes/visual/link2.obj"/>
			</geometry>
			<material name="panda_white"/>
		</visual>
		<collision>
			<geometry>
				<sphere radius="0.06"/>
			</geometry>
			<origin rpy="0 0 0" xyz="0.0 0.0 0.03"/>
		</collision>
		<collision>
			<geometry>
				<sphere radius="0.06"/>
			</geometry>
			<origin rpy="0 0 0" xyz="0.0 0.0 0.08"/>
		</collision>
		<collision>
			<geometry>
				<sphere radius="0.06"/>
			</geometry>
			<origin rpy="0 0 0" xyz="0.0 -0.12 0.0"/>
		</collision>
		<collision>
			<geometry>
				<sphere radius="0.06"/>
			</geometry>
			<origin rpy="0 0 0" xyz="0.0 -0.17 0.0"/>
		</collision>
	</link>
	<link name="left_panda_link3">
		<inertial>
			<origin rpy="0 0 0" xyz="0.01 0.01 -0.05"/>
			<mass value="2.04"/>
			<inertia ixx="0.1" ixy="0" ixz="0" iyy="0.1" iyz="0" izz="0.1"/>
		</inertial>
		<visual>
			<geometry>
				<mesh filename="meshes/visual/link3.obj"/>
			</geometry>
			<material name="left_panda_red">
				<color rgba="1. 1. 1. 1."/>
			</material>
		</visual>
		<collision>
			<geometry>
				<sphere radius="0.06"/>
			</geometry>
			<origin rpy="0 0 0" xyz="0.0 0.0 -0.1"/>
		</collision>
		<collision>
			<geometry>
				<sphere radius="0.05"/>
			</geometry>
			<origin rpy="0 0 0" xyz="0.0 0.0 -0.06"/>
		</collision>
		<collision>
			<geometry>
				<sphere radius="0.055"/>
			</geometry>
			<origin rpy="0 0 0" xyz="0.08 0.06 0.0"/>
		</collision>
		<collision>
			<geometry>
				<sphere radius="0.055"/>
			</geometry>
			<origin rpy="0 0 0" xyz="0.08 0.02 0.0"/>
		</collision>
	</link>
	<link name="left_panda_link4">
		<inertial>
			<origin rpy="0 0 0" xyz="-0.03 0.03 0.02"/>
			<mass value="2.08"/>
			<inertia ixx="0.1" ixy="0" ixz="0" iyy="0.1" iyz="0" izz="0.1"/>
		</inertial>
		<visual>
			<geometry>
				<mesh filename="meshes/visual/link4.obj"/>
			</geometry>
			<material name="panda_white"/>
		</visual>
		<collision>
			<geometry>
				<sphere radius="0.06"/>
			</geometry>
			<origin rpy="0 0 0" xyz="-0.08 0.095 0.0"/>
		</collision>
		<collision>
			<geometry>
				<sphere radius="0.055"/>
			</geometry>
			<origin rpy="0 0 0" xyz="0.0 0.0 0.02"/>
		</collision>
		<collision>
			<geometry>
				<sphere radius="0.055"/>
			</geometry>
			<origin rpy="0 0 0" xyz="0.0 0.0 0.06"/>
		</collision>
		<collision>
			<geometry>
				<sphere radius="0.055"/>
			</geometry>
			<origin rpy="0 0 0" xyz="-0.08 0.06 0.0"/>
		</collision>
	</link>
	<link name="left_panda_link5">
		<inertial>
			<origin rpy="0 0 0" xyz="0 0.04 -0.12"/>
			<mass value="3"/>
			<inertia ixx="0.1" ixy="0" ixz="0" iyy="0.1" iyz="0" izz="0.1"/>
		</inertial>
		<visual>
			<geometry>
				<mesh filename="meshes/visual/link5.obj"/>
			</geometry>
			<material name="panda_white"/>
		</visual>
		<collision>
			<geometry>
				<sphere radius="0.06"/>
			</geometry>
			<origin rpy="0 0 0" xyz="0.0 0.055 0.0"/>
		</collision>
		<collision>
			<geometry>
				<sphere radius="0.06"/>
			</geometry>
			<origin rpy="0 0 0" xyz="0.0 0.075 0.0"/>
		</collision>
		<collision>
			<geometry>
				<sphere radius="0.06"/>
			</geometry>
			<origin rpy="0 0 0" xyz="0.0 0.0 -0.22"/>
		</collision>
		<collision>
			<geometry>
				<sphere radius="0.05"/>
			</geometry>
			<origin rpy="0 0 0" xyz="0.0 0.05 -0.18"/>
		</collision>
		<collision>
			<geometry>
				<sphere radius="0.025"/>
			</geometry>
			<origin rpy="0 0 0" xyz="0.01 0.08 -0.14"/>
		</collision>
		<collision>
			<geometry>
				<sphere radius="0.025"/>
			</geometry>
			<origin rpy="0 0 0" xyz="0.01 0.085 -0.11"/>
		</collision>
		<collision>
			<geometry>
				<sphere radius="0.025"/>
			</geometry>
			<origin rpy="0 0 0" xyz="0.01 0.09 -0.08"/>
		</collision>
		<collision>
			<geometry>
				<sphere radius="0.025"/>
			</geometry>
			<origin rpy="0 0 0" xyz="0.01 0.095 -0.05"/>
		</collision>
		<collision>
			<geometry>
				<sphere radius="0.025"/>
			</geometry>
			<origin rpy="0 0 0" xyz="-0.01 0.08 -0.14"/>
		</collision>
		<collision>
			<geometry>
				<sphere radius="0.025"/>
			</geometry>
			<origin rpy="0 0 0" xyz="-0.01 0.085 -0.11"/>
		</collision>
		<collision>
			<geometry>
				<sphere radius="0.025"/>
			</geometry>
			<origin rpy="0 0 0" xyz="-0.01 0.09 -0.08"/>
		</collision>
		<collision>
			<geometry>
				<sphere radius="0.025"/>
			</geometry>
			<origin rpy="0 0 0" xyz="-0.01 0.095 -0.05"/>
		</collision>
	</link>
	<link name="left_panda_link6">
		<inertial>
			<origin rpy="0 0 0" xyz="0.04 0 0"/>
			<mass value="1.3"/>
			<inertia ixx="0.1" ixy="0" ixz="0" iyy="0.1" iyz="0" izz="0.1"/>
		</inertial>
		<visual>
			<geometry>
				<mesh filename="meshes/visual/link6.obj"/>
			</geometry>
			<material name="panda_white"/>
		</visual>
		<collision>
			<geometry>
				<sphere radius="0.05"/>
			</geometry>
			<origin rpy="0 0 0" xyz="0.0 0.0 0.0"/>
		</collision>
		<collision>
			<geometry>
				<sphere radius="0.05"/>
			</geometry>
			<origin rpy="0 0 0" xyz="0.08 -0.01 0.0"/>
		</collision>
		<collision>
			<geometry>
				<sphere radius="0.052"/>
			</geometry>
			<origin rpy="0 0 0" xyz="0.08 0.035 0.0"/>
		</collision>
	</link>
	<link name="left_panda_link7">
		<inertial>
			<origin rpy="0 0 0" xyz="0 0 0.08"/>
			<mass value=".2"/>
			<inertia ixx="0.1" ixy="0" ixz="0" iyy="0.1" iyz="0" izz="0.1"/>
		</inertial>
		<visual>
			<geometry>
				<mesh filename="meshes/collision/link7.obj"/>
			</geometry>
			<material name="panda_white"/>
		</visual>
		<collision>
			<geometry>
				<sphere radius="0.05"/>
			</geometry>
			<origin rpy="0 0 0" xyz="0.0 0.0 0.07"/>
		</collision>
		<collision>
			<geometry>
				<sphere radius="0.025"/>
			</geometry>
			<origin rpy="0 0 0" xyz="0.02 0.04 0.08"/>
		</collision>
		<collision>
			<geometry>
				<sphere radius="0.025"/>
			</geometry>
			<origin rpy="0 0 0" xyz="0.04 0.02 0.08"/>
		</collision>
		<collision>
			<geometry>
				<sphere radius="0.02"/>
			</geometry>
			<origin rpy="0 0 0" xyz="0.04 0.06 0.085"/>
		</collision>
		<collision>
			<geometry>
				<sphere radius="0.02"/>
			</geometry>
			<origin rpy="0 0 0" xyz="0.06 0.04 0.085"/>
		</collision>
	</link>
	<link name="left_panda_link8">
		<inertial>
			<origin rpy="0 0 0" xyz="0 0 0"/>
			<mass value="0.0"/>
			<inertia ixx="0.1" ixy="0" ixz="0" iyy="0.1" iyz="0" izz="0.1"/>
		</inertial>
	</link>
	<link name="left_panda_hand">
		<inertial>
			<origin rpy="0 0 0" xyz="0 0 0.04"/>
			<mass value=".81"/>
			<inertia ixx="0.1" ixy="0" ixz="0" iyy="0.1" iyz="0" izz="0.1"/>
		</inertial>
		<visual>
			<geometry>
				<mesh filename="meshes/visual/hand.obj"/>
			</geometry>
			<material name="panda_white"/>
		</visual>
		<collision>
			<geometry>
				<sphere radius="0.028"/>
			</geometry>
			<origin rpy="0 0 0" xyz="0.0 -0.075 0.01"/>
		</collision>
		<collision>
			<geometry>
				<sphere radius="0.028"/>
			</geometry>
			<origin rpy="0 0 0" xyz="0.0 -0.045 0.01"/>
		</collision>
		<collision>
			<geometry>
				<sphere radius="0.028"/>
			</geometry>
			<origin rpy="0 0 0" xyz="0.0 -0.015 0.01"/>
		</collision>
		<collision>
			<geometry>
				<sphere radius="0.028"/>
			</geometry>
			<origin rpy="0 0 0" xyz="0.0 0.015 0.01"/>
		</collision>
		<collision>
			<geometry>
				<sphere radius="0.028"/>
			</geometry>
			<origin rpy="0 0 0" xyz="0.0 0.045 0.01"/>
		</collision>
		<collision>
			<geometry>
				<sphere radius="0.028"/>
			</geometry>
			<origin rpy="0 0 0" xyz="0.0 0.075 0.01"/>
		</collision>
		<collision>
			<geometry>
				<sphere radius="0.026"/>
			</geometry>
			<origin rpy="0 0 0" xyz="0.0 -0.075 0.03"/>
		</collision>
		<collision>
			<geometry>
				<sphere radius="0.026"/>
			</geometry>
			<origin rpy="0 0 0" xyz="0.0 -0.045 0.03"/>
		</collision>
		<collision>
			<geometry>
				<sphere radius="0.026"/>
			</geometry>
			<origin rpy="0 0 0" xyz="0.0 -0.015 0.03"/>
		</collision>
		<collision>
			<geometry>
				<sphere radius="0.026"/>
			</geometry>
			<origin rpy="0 0 0" xyz="0.0 0.015 0.03"/>
		</collision>
		<collision>
			<geometry>
				<sphere radius="0.026"/>
			</geometry>
			<origin rpy="0 0 0" xyz="0.0 0.045 0.03"/>
		</collision>
		<collision>
			<geometry>
				<sphere radius="0.026"/>
			</geometry>
			<origin rpy="0 0 0" xyz="0.0 0.075 0.03"/>
		</collision>
		<collision>
			<geometry>
				<sphere radius="0.024"/>
			</geometry>
			<origin rpy="0 0 0" xyz="0.0 -0.075 0.05"/>
		</collision>
		<collision>
			<geometry>
				<sphere radius="0.024"/>
			</geometry>
			<origin rpy="0 0 0" xyz="0.0 -0.045 0.05"/>
		</collision>
		<collision>
			<geometry>
				<sphere radius="0.024"/>
			</geometry>
			<origin rpy="0 0 0" xyz="0.0 -0.015 0.05"/>
		</collision>
		<collision>
			<geometry>
				<sphere radius="0.024"/>
			</geometry>
			<origin rpy="0 0 0" xyz="0.0 0.015 0.05"/>
		</collision>
		<collision>
			<geometry>
				<sphere radius="0.024"/>
			</geometry>
			<origin rpy="0 0 0" xyz="0.0 0.045 0.05"/>
		</collision>
		<collision>
			<geometry>
				<sphere radius="0.024"/>
			</geometry>
			<origin rpy="0 0 0" xyz="0.0 0.075 0.05"/>
		</collision>
	</link>
	<link name="left_panda_leftfinger">
		<contact>
			<friction_anchor/>
			<stiffness value="30000.0"/>
			<damping value="1000.0"/>
			<spinning_friction value="0.1"/>
			<lateral_friction value="1.0"/>
		</contact>
		<inertial>
			<origin rpy="0 0 0" xyz="0 0.01 0.02"/>
			<mass value="0.1"/>
			<inertia ixx="0.1" ixy="0" ixz="0" iyy="0.1" iyz="0" izz="0.1"/>
		</inertial>
		<visual>
			<geometry>
				<mesh filename="meshes/visual/finger.obj"/>
			</geometry>
			<material name="panda_white"/>
		</visual>
		<collision>
			<geometry>
				<sphere radius="0.012"/>
			</geometry>
			<origin rpy="0 0 0" xyz="0.0 0.015 0.022"/>
		</collision>
		<collision>
			<geometry>
				<sphere radius="0.012"/>
			</geometry>
			<origin rpy="0 0 0" xyz="0.0 0.008 0.044"/>
		</collision>
	</link>
	<link name="left_panda_rightfinger">
		<contact>
			<friction_anchor/>
			<stiffness value="30000.0"/>
			<damping value="1000.0"/>
			<spinning_friction value="0.1"/>
			<lateral_friction value="1.0"/>
		</contact>
		<inertial>
			<origin rpy="0 0 0" xyz="0 -0.01 0.02"/>
			<mass value="0.1"/>
			<inertia ixx="0.1" ixy="0" ixz="0" iyy="0.1" iyz="0" izz="0.1"/>
		</inertial>
		<visual>
			<origin rpy="0 0 3.14159265359" xyz="0 0 0"/>
			<geometry>
				<mesh filename="meshes/visual/finger.obj"/>
			</geometry>
			<material name="panda_white"/>
		</visual>
		<collision>
			<geometry>
				<sphere radius="0.012"/>
			</geometry>
			<origin rpy="0 0 0" xyz="0.0 -0.015 0.022"/>
		</collision>
		<collision>
			<geometry>
				<sphere radius="0.012"/>
			</geometry>
			<origin rpy="0 0 0" xyz="0.0 -0.008 0.044"/>
		</collision>
	</link>
	<link name="left_panda_grasptarget">
		<inertial>
			<origin rpy="0 0 0" xyz="0 0 0"/>
			<mass value="0.0"/>
			<inertia ixx="0.1" ixy="0" ixz="0" iyy="0.1" iyz="0" izz="0.1"/>
		</inertial>
	</link>
	<joint name="left_panda_joint1" type="revolute">
		<safety_controller k_position="100.0" k_velocity="40.0" soft_lower_limit="-2.8973" soft_upper_limit="2.8973"/>
		<origin rpy="0 0 0" xyz="0 0 0.333"/>
		<parent link="left_panda_link0"/>
		<child link="left_panda_link1"/>
		<axis xyz="0 0 1"/>
		<limit effort="87" lower="-2.9671" upper="2.9671" velocity="2.3925"/>
	</joint>
	<joint name="left_panda_joint2" type="revolute">
		<safety_controller k_position="100.0" k_velocity="40.0" soft_lower_limit="-1.7628" soft_upper_limit="1.7628"/>
		<origin rpy="-1.57079632679 0 0" xyz="0 0 0"/>
		<parent link="left_panda_link1"/>
		<child link="left_panda_link2"/>
		<axis xyz="0 0 1"/>
		<limit effort="87" lower="-1.8326" upper="1.8326" velocity="2.3925"/>
	</joint>
	<joint name="left_panda_joint3" type="revolute">
		<safety_controller k_position="100.0" k_velocity="40.0" soft_lower_limit="-2.8973" soft_upper_limit="2.8973"/>
		<origin rpy="1.57079632679 0 0" xyz="0 -0.316 0"/>
		<parent link="left_panda_link2"/>
		<child link="left_panda_link3"/>
		<axis xyz="0 0 1"/>
		<limit effort="87" lower="-2.9671" upper="2.9671" velocity="2.3925"/>
	</joint>
	<joint name="left_panda_joint4" type="revolute">
		<safety_controller k_position="100.0" k_velocity="40.0" soft_lower_limit="-3.0718" soft_upper_limit="-0.0698"/>
		<origin rpy="1.57079632679 0 0" xyz="0.0825 0 0"/>
		<parent link="left_panda_link3"/>
		<child link="left_panda_link4"/>
		<axis xyz="0 0 1"/>
		<limit effort="87" lower="-3.1416" upper="0.0873" velocity="2.3925"/>
	</joint>
	<joint name="left_panda_joint5" type="revolute">
		<safety_controller k_position="100.0" k_velocity="40.0" soft_lower_limit="-2.8973" soft_upper_limit="2.8973"/>
		<origin rpy="-1.57079632679 0 0" xyz="-0.0825 0.384 0"/>
		<parent link="left_panda_link4"/>
		<child link="left_panda_link5"/>
		<axis xyz="0 0 1"/>
		<limit effort="12" lower="-2.9671" upper="2.9671" velocity="2.8710"/>
	</joint>
	<joint name="left_panda_joint6" type="revolute">
		<safety_controller k_position="100.0" k_velocity="40.0" soft_lower_limit="-0.0175" soft_upper_limit="3.7525"/>
		<origin rpy="1.57079632679 0 0" xyz="0 0 0"/>
		<parent link="left_panda_link5"/>
		<child link="left_panda_link6"/>
		<axis xyz="0 0 1"/>
		<limit effort="12" lower="-0.0873" upper="3.8223" velocity="2.8710"/>
	</joint>
	<joint name="left_panda_joint7" type="revolute">
		<safety_controller k_position="100.0" k_velocity="40.0" soft_lower_limit="-2.8973" soft_upper_limit="2.8973"/>
		<origin rpy="1.57079632679 0 0" xyz="0.088 0 0"/>
		<parent link="left_panda_link6"/>
		<child link="left_panda_link7"/>
		<axis xyz="0 0 1"/>
		<limit effort="12" lower="-2.9671" upper="2.9671" velocity="2.8710"/>
	</joint>
	<joint name="left_panda_joint8" type="fixed">
		<origin rpy="0 0 0" xyz="0 0 0.107"/>
		<parent link="left_panda_link7"/>
		<child link="left_panda_link8"/>
		<axis xyz="0 0 0"/>
	</joint>
	<joint name="left_panda_hand_joint" type="fixed">
		<parent link="left_panda_link8"/>
		<child link="left_panda_hand"/>
		<origin rpy="0 0 -0.785398163397" xyz="0 0 0"/>
	</joint>
	<joint name="left_panda_finger_joint1" type="fixed">
		<parent link="left_panda_hand"/>
		<child link="left_panda_leftfinger"/>
		<origin rpy="0 0 0" xyz="0 0.065 0.0584"/>
		<axis xyz="0 1 0"/>
	</joint>
	<joint name="left_panda_finger_joint2" type="fixed">
		<parent link="left_panda_hand"/>
		<child link="left_panda_rightfinger"/>
		<origin rpy="0 0 0" xyz="0 -0.065 0.0584"/>
		<axis xyz="0 -1 0"/>
		<mimic joint="left_panda_finger_joint1"/>
	</joint>
	<joint name="left_panda_grasptarget_hand" type="fixed">
		<parent link="left_panda_hand"/>
		<child link="left_panda_grasptarget"/>
		<origin rpy="0 0 0" xyz="0 0 0.105"/>
	</joint>
	<joint name="right_mount" type="fixed">
		<parent link="world"/>
		<child link="right_panda_link0"/>
		<origin rpy="0 0 0" xyz="0 0.2875 0"/>
	</joint>
	<link name="right_panda_link0">
		<inertial>
			<origin rpy="0 0 0" xyz="0 0 0.05"/>
			<mass value="2.9"/>
			<inertia ixx="0.1" ixy="0" ixz="0" iyy="0.1" iyz="0" izz="0.1"/>
		</inertial>
		<visual>
			<geometry>
				<mesh filename="meshes/collision/link0.obj"/>
			</geometry>
			<material name="panda_white">
				<color rgba="1. 1. 1. 1."/>
			</material>
		</visual>
		<collision>
			<geometry>
				<sphere radius="0.08"/>
			</geometry>
			<origin rpy="0 0 0" xyz="0.0 0.0 0.05"/>
		</collision>
	</link>
	<link name="right_panda_link1">
		<inertial>
			<origin rpy="0 0 0" xyz="0 -0.04 -0.05"/>
			<mass value="2.7"/>
			<inertia ixx="0.1" ixy="0" ixz="0" iyy="0.1" iyz="0" izz="0.1"/>
		</inertial>
		<visual>
			<geometry>
				<mesh filename="meshes/visual/link1.obj"/>
			</geometry>
			<material name="panda_white"/>
		</visual>
		<collision>
			<geometry>
				<sphere radius="0.06"/>
			</geometry>
			<origin rpy="0 0 0" xyz="0.0 -0.08 0.0"/>
		</collision>
		<collision>
			<geometry>
				<sphere radius="0.06"/>
			</geometry>
			<origin rpy="0 0 0" xyz="0.0 -0.03 0.0"/>
		</collision>
		<collision>
			<geometry>
				<sphere radius="0.06"/>
			</geometry>
			<origin rpy="0 0 0" xyz="0.0 0.0 -0.12"/>
		</collision>
		<collision>
			<geometry>
				<sphere radius="0.06"/>
			</geometry>
			<origin rpy="0 0 0" xyz="0.0 0.0 -0.17"/>
		</collision>
	</link>
	<link name="right_panda_link2">
		<inertial>
			<origin rpy="0 0 0" xyz="0 -0.04 0.06"/>
			<mass value="2.73"/>
			<inertia ixx="0.1" ixy="0" ixz="0" iyy="0.1" iyz="0" izz="0.1"/>
		</inertial>
		<visual>
			<geometry>
				<mesh filename="meshes/visual/link2.obj"/>
			</geometry>
			<material name="panda_white"/>
		</visual>
		<collision>
			<geometry>
				<sphere radius="0.06"/>
			</geometry>
			<origin rpy="0 0 0" xyz="0.0 0.0 0.03"/>
		</collision>
		<collision>
			<geometry>
				<sphere radius="0.06"/>
			</geometry>
			<origin rpy="0 0 0" xyz="0.0 0.0 0.08"/>
		</collision>
		<collision>
			<geometry>
				<sphere radius="0.06"/>
			</geometry>
			<origin rpy="0 0 0" xyz="0.0 -0.12 0.0"/>
		</collision>
		<collision>
			<geometry>
				<sphere radius="0.06"/>
			</geometry>
			<origin rpy="0 0 0" xyz="0.0 -0.17 0.0"/>
		</collision>
	</link>
	<link name="right_panda_link3">
		<inertial>
			<origin rpy="0 0 0" xyz="0.01 0.01 -0.05"/>
			<mass value="2.04"/>
			<inertia ixx="0.1" ixy="0" ixz="0" iyy="0.1" iyz="0" izz="0.1"/>
		</inertial>
		<visual>
			<geometry>
				<mesh filename="meshes/visual/link3.obj"/>
			</geometry>
			<material name="right_panda_red">
				<color rgba="1. 1. 1. 1."/>
			</material>
		</visual>
		<collision>
			<geometry>
				<sphere radius="0.06"/>
			</geometry>
			<origin rpy="0 0 0" xyz="0.0 0.0 -0.1"/>
		</collision>
		<collision>
			<geometry>
				<sphere radius="0.05"/>
			</geometry>
			<origin rpy="0 0 0" xyz="0.0 0.0 -0.06"/>
		</collision>
		<collision>
			<geometry>
				<sphere radius="0.055"/>
			</geometry>
			<origin rpy="0 0 0" xyz="0.08 0.06 0.0"/>
		</collision>
		<collision>
			<geometry>
				<sphere radius="0.055"/>
			</geometry>
			<origin rpy="0 0 0" xyz="0.08 0.02 0.0"/>
		</collision>
	</link>
	<link name="right_panda_link4">
		<inertial>
			<origin rpy="0 0 0" xyz="-0.03 0.03 0.02"/>
			<mass value="2.08"/>
			<inertia ixx="0.1" ixy="0" ixz="0" iyy="0.1" iyz="0" izz="0.1"/>
		</inertial>
		<visual>
			<geometry>
				<mesh filename="meshes/visual/link4.obj"/>
			</geometry>
			<material name="panda_white"/>
		</visual>
		<collision>
			<geometry>
				<sphere radius="0.06"/>
			</geometry>
			<origin rpy="0 0 0" xyz="-0.08 0.095 0.0"/>
		</collision>
		<collision>
			<geometry>
				<sphere radius="0.055"/>
			</geometry>
			<origin rpy="0 0 0" xyz="0.0 0.0 0.02"/>
		</collision>
		<collision>
			<geometry>
				<sphere radius="0.055"/>
			</geometry>
			<origin rpy="0 0 0" xyz="0.0 0.0 0.06"/>
		</collision>
		<collision>
			<geometry>
				<sphere radius="0.055"/>
			</geometry>
			<origin rpy="0 0 0" xyz="-0.08 0.06 0.0"/>
		</collision>
	</link>
	<link name="right_panda_link5">
		<inertial>
			<origin rpy="0 0 0" xyz="0 0.04 -0.12"/>
			<mass value="3"/>
			<inertia ixx="0.1" ixy="0" ixz="0" iyy="0.1" iyz="0" izz="0.1"/>
		</inertial>
		<visual>
			<geometry>
				<mesh filename="meshes/visual/link5.obj"/>
			</geometry>
			<material name="panda_white"/>
		</visual>
		<collision>
			<geometry>
				<sphere radius="0.06"/>
			</geometry>
			<origin rpy="0 0 0" xyz="0.0 0.055 0.0"/>
		</collision>
		<collision>
			<geometry>
				<sphere radius="0.06"/>
			</geometry>
			<origin rpy="0 0 0" xyz="0.0 0.075 0.0"/>
		</collision>
		<collision>
			<geometry>
				<sphere radius="0.06"/>
			</geometry>
			<origin rpy="0 0 0" xyz="0.0 0.0 -0.22"/>
		</collision>
		<collision>
			<geometry>
				<sphere radius="0.05"/>
			</geometry>
			<origin rpy="0 0 0" xyz="0.0 0.05 -0.18"/>
		</collision>
		<collision>
			<geometry>
				<sphere radius="0.025"/>
			</geometry>
			<origin rpy="0 0 0" xyz="0.01 0.08 -0.14"/>
		</collision>
		<collision>
			<geometry>
				<sphere radius="0.025"/>
			</geometry>
			<origin rpy="0 0 0" xyz="0.01 0.085 -0.11"/>
		</collision>
		<collision>
			<geometry>
				<sphere radius="0.025"/>
			</geometry>
			<origin rpy="0 0 0" xyz="0.01 0.09 -0.08"/>
		</collision>
		<collision>
			<geometry>
				<sphere radius="0.025"/>
			</geometry>
			<origin rpy="0 0 0" xyz="0.01 0.095 -0.05"/>
		</collision>
		<collision>
			<geometry>
				<sphere radius="0.025"/>
			</geometry>
			<origin rpy="0 0 0" xyz="-0.01 0.08 -0.14"/>
		</collision>
		<collision>
			<geometry>
				<sphere radius="0.025"/>
			</geometry>
			<origin rpy="0 0 0" xyz="-0.01 0.085 -0.11"/>
		</collision>
		<collision>
			<geometry>
				<sphere radius="0.025"/>
			</geometry>
			<origin rpy="0 0 0" xyz="-0.01 0.09 -0.08"/>
		</collision>
		<collision>
			<geometry>
				<sphere radius="0.025"/>
			</geometry>
			<origin rpy="0 0 0" xyz="-0.01 0.095 -0.05"/>
		</collision>
	</link>
	<link name="right_panda_link6">
		<inertial>
			<origin rpy="0 0 0" xyz="0.04 0 0"/>
			<mass value="1.3"/>
			<inertia ixx="0.1" ixy="0" ixz="0" iyy="0.1" iyz="0" izz="0.1"/>
		</inertial>
		<visual>
			<geometry>
				<mesh filename="meshes/visual/link6.obj"/>
			</geometry>
			<material name="panda_white"/>
		</visual>
		<collision>
			<geometry>
				<sphere radius="0.05"/>
			</geometry>
			<origin rpy="0 0 0" xyz="0.0 0.0 0.0"/>
		</collision>
		<collision>
			<geometry>
				<sphere radius="0.05"/>
			</geometry>
			<origin rpy="0 0 0" xyz="0.08 -0.01 0.0"/>
		</collision>
		<collision>
			<geometry>
				<sphere radius="0.052"/>
			</geometry>
			<origin rpy="0 0 0" xyz="0.08 0.035 0.0"/>
		</collision>
	</link>
	<link name="right_panda_link7">
		<inertial>
			<origin rpy="0 0 0" xyz="0 0 0.08"/>
			<mass value=".2"/>
			<inertia ixx="0.1" ixy="0" ixz="0" iyy="0.1" iyz="0" izz="0.1"/>
		</inertial>
		<visual>
			<geometry>
				<mesh filename="meshes/collision/link7.obj"/>
			</geometry>
			<material name="panda_white"/>
		</visual>
		<collision>
			<geometry>
				<sphere radius="0.05"/>
			</geometry>
			<origin rpy="0 0 0" xyz="0.0 0.0 0.07"/>
		</collision>
		<collision>
			<geometry>
				<sphere radius="0.025"/>
			</geometry>
			<origin rpy="0 0 0" xyz="0.02 0.04 0.08"/>
		</collision>
		<collision>
			<geometry>
				<sphere radius="0.025"/>
			</geometry>
			<origin rpy="0 0 0" xyz="0.04 0.02 0.08"/>
		</collision>
		<collision>
			<geometry>
				<sphere radius="0.02"/>
			</geometry>
			<origin rpy="0 0 0" xyz="0.04 0.06 0.085"/>
		</collision>
		<collision>
			<geometry>
				<sphere radius="0.02"/>
			</geometry>
			<origin rpy="0 0 0" xyz="0.06 0.04 0.085"/>
		</collision>
	</link>
	<link name="right_panda_link8">
		<inertial>
			<origin rpy="0 0 0" xyz="0 0 0"/>
			<mass value="0.0"/>
			<inertia ixx="0.1" ixy="0" ixz="0" iyy="0.1" iyz="0" izz="0.1"/>
		</inertial>
	</link>
	<link name="right_panda_hand">
		<inertial>
			<origin rpy="0 0 0" xyz="0 0 0.04"/>
			<mass value=".81"/>
			<inertia ixx="0.1" ixy="0" ixz="0" iyy="0.1" iyz="0" izz="0.1"/>
		</inertial>
		<visual>
			<geometry>
				<mesh filename="meshes/visual/hand.obj"/>
			</geometry>
			<material name="panda_white"/>
		</visual>
		<collision>
			<geometry>
				<sphere radius="0.028"/>
			</geometry>
			<origin rpy="0 0 0" xyz="0.0 -0.075 0.01"/>
		</collision>
		<collision>
			<geometry>
				<sphere radius="0.028"/>
			</geometry>
			<origin rpy="0 0 0" xyz="0.0 -0.045 0.01"/>
		</collision>
		<collision>
			<geometry>
				<sphere radius="0.028"/>
			</geometry>
			<origin rpy="0 0 0" xyz="0.0 -0.015 0.01"/>
		</collision>
		<collision>
			<geometry>
				<sphere radius="0.028"/>
			</geometry>
			<origin rpy="0 0 0" xyz="0.0 0.015 0.01"/>
		</collision>
		<collision>
			<geometry>
				<sphere radius="0.028"/>
			</geometry>
			<origin rpy="0 0 0" xyz="0.0 0.045 0.01"/>
		</collision>
		<collision>
			<geometry>
				<sphere radius="0.028"/>
			</geometry>
			<origin rpy="0 0 0" xyz="0.0 0.075 0.01"/>
		</collision>
		<collision>
			<geometry>
				<sphere radius="0.026"/>
			</geometry>
			<origin rpy="0 0 0" xyz="0.0 -0.075 0.03"/>
		</collision>
		<collision>
			<geometry>
				<sphere radius="0.026"/>
			</geometry>
			<origin rpy="0 0 0" xyz="0.0 -0.045 0.03"/>
		</collision>
		<collision>
			<geometry>
				<sphere radius="0.026"/>
			</geometry>
			<origin rpy="0 0 0" xyz="0.0 -0.015 0.03"/>
		</collision>
		<collision>
			<geometry>
				<sphere radius="0.026"/>
			</geometry>
			<origin rpy="0 0 0" xyz="0.0 0.015 0.03"/>
		</collision>
		<collision>
			<geometry>
				<sphere radius="0.026"/>
			</geometry>
			<origin rpy="0 0 0" xyz="0.0 0.045 0.03"/>
		</collision>
		<collision>
			<geometry>
				<sphere radius="0.026"/>
			</geometry>
			<origin rpy="0 0 0" xyz="0.0 0.075 0.03"/>
		</collision>
		<collision>
			<geometry>
				<sphere radius="0.024"/>
			</geometry>
			<origin rpy="0 0 0" xyz="0.0 -0.075 0.05"/>
		</collision>
		<collision>
			<geometry>
				<sphere radius="0.024"/>
			</geometry>
			<origin rpy="0 0 0" xyz="0.0 -0.045 0.05"/>
		</collision>
		<collision>
			<geometry>
				<sphere radius="0.024"/>
			</geometry>
			<origin rpy="0 0 0" xyz="0.0 -0.015 0.05"/>
		</collision>
		<collision>
			<geometry>
				<sphere radius="0.024"/>
			</geometry>
			<origin rpy="0 0 0" xyz="0.0 0.015 0.05"/>
		</collision>
		<collision>
			<geometry>
				<sphere radius="0.024"/>
			</geometry>
			<origin rpy="0 0 0" xyz="0.0 0.045 0.05"/>
		</collision>
		<collision>
			<geometry>
				<sphere radius="0.024"/>
			</geometry>
			<origin rpy="0 0 0" xyz="0.0 0.075 0.05"/>
		</collision>
	</link>
	<link name="right_panda_leftfinger">
		<contact>
			<friction_anchor/>
			<stiffness value="30000.0"/>
			<damping value="1000.0"/>
			<spinning_friction value="0.1"/>
			<lateral_friction value="1.0"/>
		</contact>
		<inertial>
			<origin rpy="0 0 0" xyz="0 0.01 0.02"/>
			<mass value="0.1"/>
			<inertia ixx="0.1" ixy="0" ixz="0" iyy="0.1" iyz="0" izz="0.1"/>
		</inertial>
		<visual>
			<geometry>
				<mesh filename="meshes/visual/finger.obj"/>
			</geometry>
			<material name="panda_white"/>
		</visual>
		<collision>
			<geometry>
				<sphere radius="0.012"/>
			</geometry>
			<origin rpy="0 0 0" xyz="0.0 0.015 0.022"/>
		</collision>
		<collision>
			<geometry>
				<sphere radius="0.012"/>
			</geometry>
			<origin rpy="0 0 0" xyz="0.0 0.008 0.044"/>
		</collision>
	</link>
	<link name="right_panda_rightfinger">
		<contact>
			<friction_anchor/>
			<stiffness value="30000.0"/>
			<damping value="1000.0"/>
			<spinning_friction value="0.1"/>
			<lateral_friction value="1.0"/>
		</contact>
		<inertial>
			<origin rpy="0 0 0" xyz="0 -0.01 0.02"/>
			<mass value="0.1"/>
			<inertia ixx="0.1" ixy="0" ixz="0" iyy="0.1" iyz="0" izz="0.1"/>
		</inertial>
		<visual>
			<origin rpy="0 0 3.14159265359" xyz="0 0 0"/>
			<geometry>
				<mesh filename="meshes/visual/finger.obj"/>
			</geometry>
			<material name="panda_white"/>
		</visual>
		<collision>
			<geometry>
				<sphere radius="0.012"/>
			</geometry>
			<origin rpy="0 0 0" xyz="0.0 -0.015 0.022"/>
		</collision>
		<collision>
			<geometry>
				<sphere radius="0.012"/>
			</geometry>
			<origin rpy="0 0 0" xyz="0.0 -0.008 0.044"/>
		</collision>
	</link>
	<link name="right_panda_grasptarget">
		<inertial>
			<origin rpy="0 0 0" xyz="0 0 0"/>
			<mass value="0.0"/>
			<inertia ixx="0.1" ixy="0" ixz="0" iyy="0.1" iyz="0" izz="0.1"/>
		</inertial>
	</link>
	<joint name="right_panda_joint1" type="revolute">
		<safety_controller k_position="100.0" k_velocity="40.0" soft_lower_limit="-2.8973" soft_upper_limit="2.8973"/>
		<origin rpy="0 0 0" xyz="0 0 0.333"/>
		<parent link="right_panda_link0"/>
		<child link="right_panda_link1"/>
		<axis xyz="0 0 1"/>
		<limit effort="87" lower="-2.9671" upper="2.9671" velocity="2.3925"/>
	</joint>
	<joint name="right_panda_joint2" type="revolute">
		<safety_controller k_position="100.0" k_velocity="40.0" soft_lower_limit="-1.7628" soft_upper_limit="1.7628"/>
		<origin rpy="-1.57079632679 0 0" xyz="0 0 0"/>
		<parent link="right_panda_link1"/>
		<child link="right_panda_link2"/>
		<axis xyz="0 0 1"/>
		<limit effort="87" lower="-1.8326" upper="1.8326" velocity="2.3925"/>
	</joint>
	<joint name="right_panda_joint3" type="revolute">
		<safety_controller k_position="100.0" k_velocity="40.0" soft_lower_limit="-2.8973" soft_upper_limit="2.8973"/>
		<origin rpy="1.57079632679 0 0" xyz="0 -0.316 0"/>
		<parent link="right_panda_link2"/>
		<child link="right_panda_link3"/>
		<axis xyz="0 0 1"/>
		<limit effort="87" lower="-2.9671" upper="2.9671" velocity="2.3925"/>
	</joint>
	<joint name="right_panda_joint4" type="revolute">
		<safety_controller k_position="100.0" k_velocity="40.0" soft_lower_limit="-3.0718" soft_upper_limit="-0.0698"/>
		<origin rpy="1.57079632679 0 0" xyz="0.0825 0 0"/>
		<parent link="right_panda_link3"/>
		<child link="right_panda_link4"/>
		<axis xyz="0 0 1"/>
		<limit effort="87" lower="-3.1416" upper="0.0873" velocity="2.3925"/>
	</joint>
	<joint name="right_panda_joint5" type="revolute">
		<safety_controller k_position="100.0" k_velocity="40.0" soft_lower_limit="-2.8973" soft_upper_limit="2.8973"/>
		<origin rpy="-1.57079632679 0 0" xyz="-0.0825 0.384 0"/>
		<parent link="right_panda_link4"/>
		<child link="right_panda_link5"/>
		<axis xyz="0 0 1"/>
		<limit effort="12" lower="-2.9671" upper="2.9671" velocity="2.8710"/>
	</joint>
	<joint name="right_panda_joint6" type="revolute">
		<safety_controller k_position="100.0" k_velocity="40.0" soft_lower_limit="-0.0175" soft_upper_limit="3.7525"/>
		<origin rpy="1.57079632679 0 0" xyz="0 0 0"/>
		<parent link="right_panda_link5"/>
		<child link="right_panda_link6"/>
		<axis xyz="0 0 1"/>
		<limit effort="12" lower="-0.0873" upper="3.8223" velocity="2.8710"/>
	</joint>
	<joint name="right_panda_joint7" type="revolute">
		<safety_controller k_position="100.0" k_velocity="40.0" soft_lower_limit="-2.8973" soft_upper_limit="2.8973"/>
		<origin rpy="1.57079632679 0 0" xyz="0.088 0 0"/>
		<parent link="right_panda_link6"/>
		<child link="right_panda_link7"/>
		<axis xyz="0 0 1"/>
		<limit effort="12" lower="-2.9671" upper="2.9671" velocity="2.8710"/>
	</joint>
	<joint name="right_panda_joint8" type="fixed">
		<origin rpy="0 0 0" xyz="0 0 0.107"/>
		<parent link="right_panda_link7"/>
		<child link="right_panda_link8"/>
		<axis xyz="0 0 0"/>
	</joint>
	<joint name="right_panda_hand_joint" type="fixed">
		<parent link="right_panda_link8"/>
		<child link="right_panda_hand"/>
		<origin rpy="0 0 -0.785398163397" xyz="0 0 0"/>
	</joint>
	<joint name="right_panda_finger_joint1" type="fixed">
		<parent link="right_panda_hand"/>
		<child link="right_panda_leftfinger"/>
		<origin rpy="0 0 0" xyz="0 0.065 0.0584"/>
		<axis xyz="0 1 0"/>
	</joint>
	<joint name="right_panda_finger_joint2" type="fixed">
		<parent link="right_panda_hand"/>
		<child link="right_panda_rightfinger"/>
		<origin rpy="0 0 0" xyz="0 -0.065 0.0584"/>
		<axis xyz="0 -1 0"/>
		<mimic joint="right_panda_finger_joint1"/>
	</joint>
	<joint name="right_panda_grasptarget_hand" type="fixed">
		<parent link="right_panda_hand"/>
		<child link="right_panda_grasptarget"/>
		<origin rpy="0 0 0" xyz="0 0 0.105"/>
	</joint>
</robot>
