<?xml version="1.0" encoding="utf-8"?>
<robot name="panda" xmlns:xacro="http://www.ros.org/wiki/xacro" path="resources/panda/panda_spherized_custom.urdf">
	<link name="panda_link0">
		<inertial>
			<origin rpy="0 0 0" xyz="0 0 0.05"></origin>
			<mass value="2.9"></mass>
			<inertia ixx="0.1" ixy="0" ixz="0" iyy="0.1" iyz="0" izz="0.1"></inertia>
		</inertial>
		<visual>
			<geometry>
				<mesh filename="meshes/collision/link0.obj"></mesh>
			</geometry>
			<material name="panda_white">
				<color rgba="1. 1. 1. 1."></color>
			</material>
		</visual>
		<collision>
			<geometry>
				<sphere radius="0.08"></sphere>
			</geometry>
			<origin xyz="0.0 0.0 0.05" rpy="0 0 0"></origin>
		</collision>
	</link>
	<link name="panda_link1">
		<inertial>
			<origin rpy="0 0 0" xyz="0 -0.04 -0.05"></origin>
			<mass value="2.7"></mass>
			<inertia ixx="0.1" ixy="0" ixz="0" iyy="0.1" iyz="0" izz="0.1"></inertia>
		</inertial>
		<visual>
			<geometry>
				<mesh filename="meshes/visual/link1.obj"></mesh>
			</geometry>
			<material name="panda_white"></material>
		</visual>
		<collision>
			<geometry>
				<sphere radius="0.154"></sphere>
			</geometry>
			<origin xyz="-0.001 -0.039 -0.085" rpy="0 0 0"></origin>
		</collision>
	</link>
	<link name="panda_link2">
		<inertial>
			<origin rpy="0 0 0" xyz="0 -0.04 0.06"></origin>
			<mass value="2.73"></mass>
			<inertia ixx="0.1" ixy="0" ixz="0" iyy="0.1" iyz="0" izz="0.1"></inertia>
		</inertial>
		<visual>
			<geometry>
				<mesh filename="meshes/visual/link2.obj"></mesh>
			</geometry>
			<material name="panda_white"></material>
		</visual>
		<collision>
			<geometry>
				<sphere radius="0.154"></sphere>
			</geometry>
			<origin xyz="0.0 -0.085 0.04" rpy="0 0 0"></origin>
		</collision>
	</link>
	<link name="panda_link3">
		<inertial>
			<origin rpy="0 0 0" xyz="0.01 0.01 -0.05"></origin>
			<mass value="2.04"></mass>
			<inertia ixx="0.1" ixy="0" ixz="0" iyy="0.1" iyz="0" izz="0.1"></inertia>
		</inertial>
		<visual>
			<geometry>
				<mesh filename="meshes/visual/link3.obj"></mesh>
			</geometry>
			<material name="panda_red">
				<color rgba="1. 1. 1. 1."></color>
			</material>
		</visual>
		<collision>
			<geometry>
				<sphere radius="0.128"></sphere>
			</geometry>
			<origin xyz="0.039 0.028 -0.052" rpy="0 0 0"></origin>
		</collision>
	</link>
	<link name="panda_link4">
		<inertial>
			<origin rpy="0 0 0" xyz="-0.03 0.03 0.02"></origin>
			<mass value="2.08"></mass>
			<inertia ixx="0.1" ixy="0" ixz="0" iyy="0.1" iyz="0" izz="0.1"></inertia>
		</inertial>
		<visual>
			<geometry>
				<mesh filename="meshes/visual/link4.obj"></mesh>
			</geometry>
			<material name="panda_white"></material>
		</visual>
		<collision>
			<geometry>
				<sphere radius="0.126"></sphere>
			</geometry>
			<origin xyz="-0.042 0.049 0.029" rpy="0 0 0"></origin>
		</collision>
	</link>
	<link name="panda_link5">
		<inertial>
			<origin rpy="0 0 0" xyz="0 0.04 -0.12"></origin>
			<mass value="3"></mass>
			<inertia ixx="0.1" ixy="0" ixz="0" iyy="0.1" iyz="0" izz="0.1"></inertia>
		</inertial>
		<visual>
			<geometry>
				<mesh filename="meshes/visual/link5.obj"></mesh>
			</geometry>
			<material name="panda_white"></material>
		</visual>
		<collision>
			<geometry>
				<sphere radius="0.176"></sphere>
			</geometry>
			<origin xyz="-0.001 0.037 -0.11" rpy="0 0 0"></origin>
		</collision>
	</link>
	<link name="panda_link6">
		<inertial>
			<origin rpy="0 0 0" xyz="0.04 0 0"></origin>
			<mass value="1.3"></mass>
			<inertia ixx="0.1" ixy="0" ixz="0" iyy="0.1" iyz="0" izz="0.1"></inertia>
		</inertial>
		<visual>
			<geometry>
				<mesh filename="meshes/visual/link6.obj"></mesh>
			</geometry>
			<material name="panda_white"></material>
		</visual>
		<collision>
			<geometry>
				<sphere radius="0.095"></sphere>
			</geometry>
			<origin xyz="0.042 0.014 0.0" rpy="0 0 0"></origin>
		</collision>
	</link>
	<link name="panda_link7">
		<inertial>
			<origin rpy="0 0 0" xyz="0 0 0.08"></origin>
			<mass value=".2"></mass>
			<inertia ixx="0.1" ixy="0" ixz="0" iyy="0.1" iyz="0" izz="0.1"></inertia>
		</inertial>
		<visual>
			<geometry>
				<mesh filename="meshes/collision/link7.obj"></mesh>
			</geometry>
			<material name="panda_white"></material>
		</visual>
		<collision>
			<geometry>
				<sphere radius="0.072"></sphere>
			</geometry>
			<origin xyz="0.015 0.015 0.075" rpy="0 0 0"></origin>
		</collision>
	</link>
	<link name="panda_link8">
		<inertial>
			<origin rpy="0 0 0" xyz="0 0 0"></origin>
			<mass value="0.0"></mass>
			<inertia ixx="0.1" ixy="0" ixz="0" iyy="0.1" iyz="0" izz="0.1"></inertia>
		</inertial>
	</link>
	<link name="panda_hand">
		<inertial>
			<origin rpy="0 0 0" xyz="0 0 0.04"></origin>
			<mass value=".81"></mass>
			<inertia ixx="0.1" ixy="0" ixz="0" iyy="0.1" iyz="0" izz="0.1"></inertia>
		</inertial>
		<visual>
			<geometry>
				<mesh filename="meshes/visual/hand.obj"></mesh>
			</geometry>
			<material name="panda_white"></material>
		</visual>
		<collision>
			<geometry>
				<sphere radius="0.104"></sphere>
			</geometry>
			<origin xyz="0.0 -0.0 0.022" rpy="0 0 0"></origin>
		</collision>
	</link>
	<link name="panda_leftfinger">
		<contact>
			<friction_anchor></friction_anchor>
			<stiffness value="30000.0"></stiffness>
			<damping value="1000.0"></damping>
			<spinning_friction value="0.1"></spinning_friction>
			<lateral_friction value="1.0"></lateral_friction>
		</contact>
		<inertial>
			<origin rpy="0 0 0" xyz="0 0.01 0.02"></origin>
			<mass value="0.1"></mass>
			<inertia ixx="0.1" ixy="0" ixz="0" iyy="0.1" iyz="0" izz="0.1"></inertia>
		</inertial>
		<visual>
			<geometry>
				<mesh filename="meshes/visual/finger.obj"></mesh>
			</geometry>
			<material name="panda_white"></material>
		</visual>
		<collision>
			<geometry>
				<sphere radius="0.024"></sphere>
			</geometry>
			<origin xyz="0.0 0.012 0.033" rpy="0 0 0"></origin>
		</collision>
	</link>
	<link name="panda_rightfinger">
		<contact>
			<friction_anchor></friction_anchor>
			<stiffness value="30000.0"></stiffness>
			<damping value="1000.0"></damping>
			<spinning_friction value="0.1"></spinning_friction>
			<lateral_friction value="1.0"></lateral_friction>
		</contact>
		<inertial>
			<origin rpy="0 0 0" xyz="0 -0.01 0.02"></origin>
			<mass value="0.1"></mass>
			<inertia ixx="0.1" ixy="0" ixz="0" iyy="0.1" iyz="0" izz="0.1"></inertia>
		</inertial>
		<visual>
			<origin rpy="0 0 3.14159265359" xyz="0 0 0"></origin>
			<geometry>
				<mesh filename="meshes/visual/finger.obj"></mesh>
			</geometry>
			<material name="panda_white"></material>
		</visual>
		<collision>
			<geometry>
				<sphere radius="0.024"></sphere>
			</geometry>
			<origin xyz="0.0 -0.012 0.033" rpy="0 0 0"></origin>
		</collision>
	</link>
	<link name="panda_grasptarget">
		<inertial>
			<origin rpy="0 0 0" xyz="0 0 0"></origin>
			<mass value="0.0"></mass>
			<inertia ixx="0.1" ixy="0" ixz="0" iyy="0.1" iyz="0" izz="0.1"></inertia>
		</inertial>
	</link>
	<joint name="panda_joint1" type="revolute">
		<safety_controller k_position="100.0" k_velocity="40.0" soft_lower_limit="-2.8973" soft_upper_limit="2.8973"></safety_controller>
		<origin rpy="0 0 0" xyz="0 0 0.333"></origin>
		<parent link="panda_link0"></parent>
		<child link="panda_link1"></child>
		<axis xyz="0 0 1"></axis>
		<limit effort="87" lower="-2.9671" upper="2.9671" velocity="2.3925"></limit>
	</joint>
	<joint name="panda_joint2" type="revolute">
		<safety_controller k_position="100.0" k_velocity="40.0" soft_lower_limit="-1.7628" soft_upper_limit="1.7628"></safety_controller>
		<origin rpy="-1.57079632679 0 0" xyz="0 0 0"></origin>
		<parent link="panda_link1"></parent>
		<child link="panda_link2"></child>
		<axis xyz="0 0 1"></axis>
		<limit effort="87" lower="-1.8326" upper="1.8326" velocity="2.3925"></limit>
	</joint>
	<joint name="panda_joint3" type="revolute">
		<safety_controller k_position="100.0" k_velocity="40.0" soft_lower_limit="-2.8973" soft_upper_limit="2.8973"></safety_controller>
		<origin rpy="1.57079632679 0 0" xyz="0 -0.316 0"></origin>
		<parent link="panda_link2"></parent>
		<child link="panda_link3"></child>
		<axis xyz="0 0 1"></axis>
		<limit effort="87" lower="-2.9671" upper="2.9671" velocity="2.3925"></limit>
	</joint>
	<joint name="panda_joint4" type="revolute">
		<safety_controller k_position="100.0" k_velocity="40.0" soft_lower_limit="-3.0718" soft_upper_limit="-0.0698"></safety_controller>
		<origin rpy="1.57079632679 0 0" xyz="0.0825 0 0"></origin>
		<parent link="panda_link3"></parent>
		<child link="panda_link4"></child>
		<axis xyz="0 0 1"></axis>
		<limit effort="87" lower="-3.1416" upper="0.0873" velocity="2.3925"></limit>
	</joint>
	<joint name="panda_joint5" type="revolute">
		<safety_controller k_position="100.0" k_velocity="40.0" soft_lower_limit="-2.8973" soft_upper_limit="2.8973"></safety_controller>
		<origin rpy="-1.57079632679 0 0" xyz="-0.0825 0.384 0"></origin>
		<parent link="panda_link4"></parent>
		<child link="panda_link5"></child>
		<axis xyz="0 0 1"></axis>
		<limit effort="12" lower="-2.9671" upper="2.9671" velocity="2.8710"></limit>
	</joint>
	<joint name="panda_joint6" type="revolute">
		<safety_controller k_position="100.0" k_velocity="40.0" soft_lower_limit="-0.0175" soft_upper_limit="3.7525"></safety_controller>
		<origin rpy="1.57079632679 0 0" xyz="0 0 0"></origin>
		<parent link="panda_link5"></parent>
		<child link="panda_link6"></child>
		<axis xyz="0 0 1"></axis>
		<limit effort="12" lower="-0.0873" upper="3.8223" velocity="2.8710"></limit>
	</joint>
	<joint name="panda_joint7" type="revolute">
		<safety_controller k_position="100.0" k_velocity="40.0" soft_lower_limit="-2.8973" soft_upper_limit="2.8973"></safety_controller>
		<origin rpy="1.57079632679 0 0" xyz="0.088 0 0"></origin>
		<parent link="panda_link6"></parent>
		<child link="panda_link7"></child>
		<axis xyz="0 0 1"></axis>
		<limit effort="12" lower="-2.9671" upper="2.9671" velocity="2.8710"></limit>
	</joint>
	<joint name="panda_joint8" type="fixed">
		<origin rpy="0 0 0" xyz="0 0 0.107"></origin>
		<parent link="panda_link7"></parent>
		<child link="panda_link8"></child>
		<axis xyz="0 0 0"></axis>
	</joint>
	<joint name="panda_hand_joint" type="fixed">
		<parent link="panda_link8"></parent>
		<child link="panda_hand"></child>
		<origin rpy="0 0 -0.785398163397" xyz="0 0 0"></origin>
	</joint>
	<joint name="panda_finger_joint1" type="fixed">
		<parent link="panda_hand"></parent>
		<child link="panda_leftfinger"></child>
		<origin rpy="0 0 0" xyz="0 0.065 0.0584"></origin>
		<axis xyz="0 1 0"></axis>
	</joint>
	<joint name="panda_finger_joint2" type="fixed">
		<parent link="panda_hand"></parent>
		<child link="panda_rightfinger"></child>
		<origin rpy="0 0 0" xyz="0 -0.065 0.0584"></origin>
		<axis xyz="0 -1 0"></axis>
		<mimic joint="panda_finger_joint1"></mimic>
	</joint>
	<joint name="panda_grasptarget_hand" type="fixed">
		<parent link="panda_hand"></parent>
		<child link="panda_grasptarget"></child>
		<origin rpy="0 0 0" xyz="0 0 0.105"></origin>
	</joint>
</robot>