<?xml version="1.0" encoding="utf-8"?>
<robot name="ur5_robotiq85" path="ur5_spherized.urdf">
	<link name="offset_link"></link>
	<link name="base_link">
		<visual>
			<geometry>
				<mesh filename="package://meshes/ur5/visual/base.dae"></mesh>
			</geometry>
		</visual>
		<collision>
			<geometry>
				<sphere radius="0.08"></sphere>
			</geometry>
			<origin xyz="0.0 0.0 0.0" rpy="0 0 0"></origin>
		</collision>
		<inertial>
			<mass value="4.0"></mass>
			<origin rpy="0 0 0" xyz="0.0 0.0 0.0"></origin>
			<inertia ixx="0.00443333156" ixy="0.0" ixz="0.0" iyy="0.00443333156" iyz="0.0" izz="0.0072"></inertia>
		</inertial>
	</link>
	<link name="shoulder_link">
		<visual>
			<geometry>
				<mesh filename="package://meshes/ur5/visual/shoulder.dae"></mesh>
			</geometry>
		</visual>
		<collision>
			<geometry>
				<sphere radius="0.08"></sphere>
			</geometry>
			<origin xyz="0.0 0.0 0.0" rpy="0 0 0"></origin>
		</collision>
		<inertial>
			<mass value="3.7"></mass>
			<origin rpy="0 0 0" xyz="0.0 0.0 0.0"></origin>
			<inertia ixx="0.010267495893" ixy="0.0" ixz="0.0" iyy="0.010267495893" iyz="0.0" izz="0.00666"></inertia>
		</inertial>
	</link>
	<link name="upper_arm_link">
		<visual>
			<geometry>
				<mesh filename="package://meshes/ur5/visual/upperarm.dae"></mesh>
			</geometry>
		</visual>
		<collision>
			<geometry>
				<sphere radius="0.29"></sphere>
			</geometry>
			<origin xyz="-0.0 0.0 0.21" rpy="0 0 0"></origin>
		</collision>
		<inertial>
			<mass value="8.393"></mass>
			<origin rpy="0 0 0" xyz="0.0 0.0 0.28"></origin>
			<inertia ixx="0.22689067591036005" ixy="0.0" ixz="0.0" iyy="0.22689067591036005" iyz="0.0" izz="0.0151074"></inertia>
		</inertial>
	</link>
	<link name="forearm_link">
		<visual>
			<geometry>
				<mesh filename="package://meshes/ur5/visual/forearm.dae"></mesh>
			</geometry>
		</visual>
		<collision>
			<geometry>
				<sphere radius="0.265"></sphere>
			</geometry>
			<origin xyz="0.002 0.003 0.185" rpy="0 0 0"></origin>
		</collision>
		<inertial>
			<mass value="2.275"></mass>
			<origin rpy="0 0 0" xyz="0.0 0.0 0.25"></origin>
			<inertia ixx="0.04944331355599999" ixy="0.0" ixz="0.0" iyy="0.04944331355599999" iyz="0.0" izz="0.004095"></inertia>
		</inertial>
	</link>
	<link name="wrist_1_link">
		<visual>
			<geometry>
				<mesh filename="package://meshes/ur5/visual/wrist1.dae"></mesh>
			</geometry>
		</visual>
		<collision>
			<geometry>
				<sphere radius="0.07"></sphere>
			</geometry>
			<origin xyz="0.0 0.09 -0.0" rpy="0 0 0"></origin>
		</collision>
		<inertial>
			<mass value="1.219"></mass>
			<origin rpy="0 0 0" xyz="0.0 0.0 0.0"></origin>
			<inertia ixx="0.11117275553087999" ixy="0.0" ixz="0.0" iyy="0.11117275553087999" iyz="0.0" izz="0.21942"></inertia>
		</inertial>
	</link>
	<link name="wrist_2_link">
		<visual>
			<geometry>
				<mesh filename="package://meshes/ur5/visual/wrist2.dae"></mesh>
			</geometry>
		</visual>
		<collision>
			<geometry>
				<sphere radius="0.07"></sphere>
			</geometry>
			<origin xyz="0.0 0.0 0.09" rpy="0 0 0"></origin>
		</collision>
		<inertial>
			<mass value="1.219"></mass>
			<origin rpy="0 0 0" xyz="0.0 0.0 0.0"></origin>
			<inertia ixx="0.11117275553087999" ixy="0.0" ixz="0.0" iyy="0.11117275553087999" iyz="0.0" izz="0.21942"></inertia>
		</inertial>
	</link>
	<link name="wrist_3_link">
		<visual>
			<geometry>
				<mesh filename="package://meshes/ur5/visual/wrist3.dae"></mesh>
			</geometry>
		</visual>
		<collision>
			<geometry>
				<sphere radius="0.04"></sphere>
			</geometry>
			<origin xyz="0.0 0.06 0.0" rpy="0 0 0"></origin>
		</collision>
		<inertial>
			<mass value="0.1879"></mass>
			<origin rpy="0 0 0" xyz="0.0 0.0 0.0"></origin>
			<inertia ixx="0.017136473145408" ixy="0.0" ixz="0.0" iyy="0.017136473145408" iyz="0.0" izz="0.033822"></inertia>
		</inertial>
	</link>
	<link name="ee_link"></link>
	<link name="tool0"></link>
	<link name="fts_robotside">
		<inertial>
			<origin rpy="0 0 0" xyz="0 0 0.01875"></origin>
			<mass value="0.65"></mass>
			<inertia ixx="0.000661171875" ixy="0" ixz="0" iyy="0.000661171875" iyz="0" izz="0.00117"></inertia>
		</inertial>
		<visual>
			<origin rpy="0 0 0" xyz="0 0 0"></origin>
			<geometry>
				<mesh filename="package://meshes/robotiq_fts300.stl"></mesh>
			</geometry>
		</visual>
		<collision>
			<geometry>
				<sphere radius="0.04"></sphere>
			</geometry>
			<origin xyz="0.0 -0.02 0.0" rpy="0 0 0"></origin>
		</collision>
	</link>
	<link name="robotiq_force_torque_frame_id"></link>
	<link name="fts_toolside"></link>
	<link name="robotiq_85_base_link">
		<inertial>
			<origin xyz="0.00021987 -2.3546E-10 0.030163" rpy="0 0 0"></origin>
			<mass value="0.30915"></mass>
			<inertia ixx="0.00028972" ixy="-5.7879E-10" ixz="-1.8543E-06" iyy="0.00030737" iyz="1.682E-12" izz="0.00019914"></inertia>
		</inertial>
		<visual>
			<origin xyz="0 0 0" rpy="0 0 0"></origin>
			<geometry>
				<mesh filename="package://meshes/robotiq/robotiq_85_base_link_fine.STL"></mesh>
			</geometry>
		</visual>
		<collision>
			<geometry>
				<sphere radius="0.06"></sphere>
			</geometry>
			<origin xyz="0.0 -0.0 0.04" rpy="0 0 0"></origin>
		</collision>
	</link>
	<link name="robotiq_85_left_knuckle_link">
		<inertial>
			<origin xyz="0.0178331863169983 3.68915177224286E-11 0.0021442477325704" rpy="0 0 0"></origin>
			<mass value="0.00684838849434396"></mass>
			<inertia ixx="2.66832029033166E-07" ixy="1.66142314639824E-15" ixz="1.45945633322873E-07" iyy="1.3889233257419E-06" iyz="2.82951161241588E-15" izz="1.26603336914415E-06"></inertia>
		</inertial>
		<visual>
			<origin xyz="0 0 0" rpy="0 0 0"></origin>
			<geometry>
				<mesh filename="meshes/robotiq/outer_knuckle_fine.STL"></mesh>
			</geometry>
		</visual>
		<collision>
			<geometry>
				<sphere radius="0.02"></sphere>
			</geometry>
			<origin xyz="0.0 0.0 0.0" rpy="0 0 0"></origin>
		</collision>
	</link>
	<link name="robotiq_85_left_finger_link">
		<inertial>
			<origin xyz="0.00131451599174296 2.88942057994543E-15 0.0215404163180413" rpy="0 0 0"></origin>
			<mass value="0.0273093985570947"></mass>
			<inertia ixx="8.51629628283022E-06" ixy="2.58174336207405E-19" ixz="3.83829504344079E-07" iyy="6.9133328065108E-06" iyz="-7.58589926143789E-19" izz="2.25006832221981E-06"></inertia>
		</inertial>
		<visual>
			<origin xyz="0 0 0" rpy="0 0 0"></origin>
			<geometry>
				<mesh filename="meshes/robotiq/outer_finger_fine.STL"></mesh>
			</geometry>
			<material name="">
				<color rgba="0.1 0.1 0.1 1"></color>
			</material>
		</visual>
		<collision>
			<geometry>
				<sphere radius="0.035"></sphere>
			</geometry>
			<origin xyz="-0.0 -0.0 0.02" rpy="0 0 0"></origin>
		</collision>
	</link>
	<link name="robotiq_85_left_inner_knuckle_link">
		<inertial>
			<origin xyz="0.017097546626628 -3.93808524389535E-10 0.0224918438201868" rpy="0 0 0"></origin>
			<mass value="0.0110930853895903"></mass>
			<inertia ixx="4.23392770691541E-06" ixy="5.748978936968E-15" ixz="1.78855677119788E-06" iyy="3.96548790524392E-06" iyz="1.05464666369669E-14" izz="3.24068002883007E-06"></inertia>
		</inertial>
		<visual>
			<origin xyz="0 0 0" rpy="0 0 0"></origin>
			<geometry>
				<mesh filename="meshes/robotiq/inner_knuckle_fine.STL"></mesh>
			</geometry>
			<material name="">
				<color rgba="0.1 0.1 0.1 1"></color>
			</material>
		</visual>
		<collision>
			<geometry>
				<sphere radius="0.02"></sphere>
			</geometry>
			<origin xyz="0.02 0.0 0.02" rpy="0 0 0"></origin>
		</collision>
	</link>
	<link name="robotiq_85_left_finger_tip_link">
		<inertial>
			<origin xyz="0.0060275613594574 -6.29183141465421E-15 0.00669925693133241" rpy="0 0 0"></origin>
			<mass value="0.00724255346165745"></mass>
			<inertia ixx="1.47824274053603E-06" ixy="-3.94884463570303E-19" ixz="-3.45268847648622E-07" iyy="1.70064480838395E-06" iyz="3.5059838910097E-19" izz="4.77151336838364E-07"></inertia>
		</inertial>
		<visual>
			<origin xyz="0 0 0" rpy="0 0 0"></origin>
			<geometry>
				<mesh filename="meshes/robotiq/inner_finger_fine.STL"></mesh>
			</geometry>
			<material name="">
				<color rgba="0.1 0.1 0.1 1"></color>
			</material>
		</visual>
		<collision>
			<geometry>
				<sphere radius="0.033"></sphere>
			</geometry>
			<origin xyz="0.0 0.0 0.013" rpy="0 0 0"></origin>
		</collision>
	</link>
	<link name="robotiq_85_right_inner_knuckle_link">
		<inertial>
			<origin xyz="0.0168606186773776 3.93808471820465E-10 0.0226699950793434" rpy="0 0 0"></origin>
			<mass value="0.0110930853895903"></mass>
			<inertia ixx="4.27134775939882E-06" ixy="-8.53568456728898E-15" ixz="1.77774229944246E-06" iyy="3.96548790524392E-06" iyz="-8.45108024914164E-15" izz="3.20325997634666E-06"></inertia>
		</inertial>
		<visual>
			<origin xyz="0 0 0" rpy="0 0 0"></origin>
			<geometry>
				<mesh filename="meshes/robotiq/inner_knuckle_fine.STL"></mesh>
			</geometry>
			<material name="">
				<color rgba="0.1 0.1 0.1 1"></color>
			</material>
		</visual>
		<collision>
			<geometry>
				<sphere radius="0.02"></sphere>
			</geometry>
			<origin xyz="0.02 0.0 0.02" rpy="0 0 0"></origin>
		</collision>
	</link>
	<link name="robotiq_85_right_finger_tip_link">
		<inertial>
			<origin xyz="0.00602756228812038 -6.47284509480176E-15 0.00669925609578108" rpy="0 0 0"></origin>
			<mass value="0.00724255346165744"></mass>
			<inertia ixx="1.47824283625957E-06" ixy="-3.95952064019123E-19" ixz="-3.45268708875543E-07" iyy="1.70064480838394E-06" iyz="3.55286507960029E-19" izz="4.77151241114822E-07"></inertia>
		</inertial>
		<visual>
			<origin xyz="0 0 0" rpy="0 0 0"></origin>
			<geometry>
				<mesh filename="meshes/robotiq/inner_finger_fine.STL"></mesh>
			</geometry>
			<material name="">
				<color rgba="0.1 0.1 0.1 1"></color>
			</material>
		</visual>
		<collision>
			<geometry>
				<sphere radius="0.033"></sphere>
			</geometry>
			<origin xyz="0.0 0.0 0.013" rpy="0 0 0"></origin>
		</collision>
	</link>
	<link name="robotiq_85_right_knuckle_link">
		<inertial>
			<origin xyz="0.0178097074051638 3.60493211424024E-11 0.00233123458346721" rpy="0 0 0"></origin>
			<mass value="0.00684838849401352"></mass>
			<inertia ixx="2.70004361573169E-07" ixy="1.59579467624491E-15" ixz="1.56396493788199E-07" iyy="1.38892332558312E-06" iyz="2.82357800318817E-15" izz="1.26286103637978E-06"></inertia>
		</inertial>
		<visual>
			<origin xyz="0 0 0" rpy="0 0 0"></origin>
			<geometry>
				<mesh filename="meshes/robotiq/outer_knuckle_fine.STL"></mesh>
			</geometry>
			<material name="">
				<color rgba="0.1 0.1 0.1 1"></color>
			</material>
		</visual>
		<collision>
			<geometry>
				<sphere radius="0.02"></sphere>
			</geometry>
			<origin xyz="0.0 0.0 0.0" rpy="0 0 0"></origin>
		</collision>
	</link>
	<link name="robotiq_85_right_finger_link">
		<inertial>
			<origin xyz="0.00108844269639009 -2.611488350845E-15 0.0215530225245502" rpy="0 0 0"></origin>
			<mass value="0.0273093985570947"></mass>
			<inertia ixx="8.52366028592721E-06" ixy="3.41683380899422E-19" ixz="3.18003675694284E-07" iyy="6.91333280651081E-06" iyz="7.37726682706417E-19" izz="2.24270431912283E-06"></inertia>
		</inertial>
		<visual>
			<origin xyz="0 0 0" rpy="0 0 0"></origin>
			<geometry>
				<mesh filename="meshes/robotiq/outer_finger_fine.STL"></mesh>
			</geometry>
			<material name="">
				<color rgba="0.1 0.1 0.1 1"></color>
			</material>
		</visual>
		<collision>
			<geometry>
				<sphere radius="0.035"></sphere>
			</geometry>
			<origin xyz="-0.0 -0.0 0.02" rpy="0 0 0"></origin>
		</collision>
	</link>
	<joint name="offset_joint" type="fixed">
		<parent link="offset_link"></parent>
		<child link="base_link"></child>
		<origin xyz="0.0 0.0 0.9144" rpy="0 0 1.57"></origin>
	</joint>
	<joint name="shoulder_pan_joint" type="revolute">
		<parent link="base_link"></parent>
		<child link="shoulder_link"></child>
		<origin rpy="0 0.0 0" xyz="0.0 0.0 0.089159"></origin>
		<axis xyz="0 0 1"></axis>
		<limit effort="150.0" lower="-3.14159265" upper="3.14159265" velocity="0.5"></limit>
		<dynamics damping="0.0" friction="0.0"></dynamics>
	</joint>
	<joint name="shoulder_lift_joint" type="revolute">
		<parent link="shoulder_link"></parent>
		<child link="upper_arm_link"></child>
		<origin rpy="0.0 1.570796325 0.0" xyz="0.0 0.13585 0.0"></origin>
		<axis xyz="0 1 0"></axis>
		<limit effort="150.0" lower="-3.14159265" upper="3.14159265" velocity="0.5"></limit>
		<dynamics damping="0.0" friction="0.0"></dynamics>
	</joint>
	<joint name="elbow_joint" type="revolute">
		<parent link="upper_arm_link"></parent>
		<child link="forearm_link"></child>
		<origin rpy="0.0 0.0 0.0" xyz="0.0 -0.1197 0.425"></origin>
		<axis xyz="0 1 0"></axis>
		<limit effort="150.0" lower="-3.14159265" upper="3.14159265" velocity="0.5"></limit>
		<dynamics damping="0.0" friction="0.0"></dynamics>
	</joint>
	<joint name="wrist_1_joint" type="revolute">
		<parent link="forearm_link"></parent>
		<child link="wrist_1_link"></child>
		<origin rpy="0.0 1.570796325 0.0" xyz="0.0 0.0 0.39225"></origin>
		<axis xyz="0 1 0"></axis>
		<limit effort="28.0" lower="-3.14159265" upper="3.14159265" velocity="0.5"></limit>
		<dynamics damping="0.0" friction="0.0"></dynamics>
	</joint>
	<joint name="wrist_2_joint" type="revolute">
		<parent link="wrist_1_link"></parent>
		<child link="wrist_2_link"></child>
		<origin rpy="0.0 0.0 0.0" xyz="0.0 0.093 0.0"></origin>
		<axis xyz="0 0 1"></axis>
		<limit effort="28.0" lower="-3.14159265" upper="3.14159265" velocity="0.5"></limit>
		<dynamics damping="0.0" friction="0.0"></dynamics>
	</joint>
	<joint name="wrist_3_joint" type="revolute">
		<parent link="wrist_2_link"></parent>
		<child link="wrist_3_link"></child>
		<origin rpy="0.0 0.0 0.0" xyz="0.0 0.0 0.09465"></origin>
		<axis xyz="0 1 0"></axis>
		<limit effort="28.0" lower="-3.14159265" upper="3.14159265" velocity="0.5"></limit>
		<dynamics damping="0.0" friction="0.0"></dynamics>
	</joint>
	<joint name="ee_fixed_joint" type="fixed">
		<parent link="wrist_3_link"></parent>
		<child link="ee_link"></child>
		<origin rpy="0.0 0.0 1.570796325" xyz="0.0 0.0823 0.0"></origin>
	</joint>
	<joint name="wrist_3_link-tool0_fixed_joint" type="fixed">
		<origin rpy="-1.570796325 0 0" xyz="0 0.0823 0"></origin>
		<parent link="wrist_3_link"></parent>
		<child link="tool0"></child>
	</joint>
	<joint name="fts_fix" type="fixed">
		<origin rpy="0.0 0 -1.57" xyz="0.035 0 0.0"></origin>
		<parent link="ee_link"></parent>
		<child link="fts_robotside"></child>
	</joint>
	<joint name="measurment_joint" type="fixed">
		<origin rpy="0 0 0" xyz="0 0 0.01625"></origin>
		<parent link="fts_robotside"></parent>
		<child link="robotiq_force_torque_frame_id"></child>
	</joint>
	<joint name="toolside_joint" type="fixed">
		<origin rpy="0 0 0" xyz="0 0 0.0375"></origin>
		<parent link="fts_robotside"></parent>
		<child link="fts_toolside"></child>
	</joint>
	<joint name="robotiq_85_base_joint" type="fixed">
		<parent link="fts_toolside"></parent>
		<child link="robotiq_85_base_link"></child>
		<origin rpy="-1.57 0.0 0.0" xyz="0.0 0.0 -0.037"></origin>
	</joint>
	<joint name="robotiq_85_left_knuckle_joint" type="fixed">
		<origin xyz="0.0306011444260539 0 0.0627920162695395" rpy="0 0 0"></origin>
		<parent link="robotiq_85_base_link"></parent>
		<child link="robotiq_85_left_knuckle_link"></child>
		<axis xyz="0 -1 0"></axis>
	</joint>
	<joint name="robotiq_85_left_finger_joint" type="fixed">
		<origin xyz="0.0316910442266543 0 -0.00193396375724605" rpy="0 0 0"></origin>
		<parent link="robotiq_85_left_knuckle_link"></parent>
		<child link="robotiq_85_left_finger_link"></child>
		<axis xyz="0 -1 0"></axis>
	</joint>
	<joint name="robotiq_85_left_inner_knuckle_joint" type="fixed">
		<origin xyz="0.0127000000001501 0 0.0693074999999639" rpy="0 0 0"></origin>
		<parent link="robotiq_85_base_link"></parent>
		<child link="robotiq_85_left_inner_knuckle_link"></child>
		<axis xyz="0 -1 0"></axis>
	</joint>
	<joint name="robotiq_85_left_finger_tip_joint" type="fixed">
		<origin xyz="0.034585310861294 0 0.0454970193817975" rpy="0 0 0"></origin>
		<parent link="robotiq_85_left_inner_knuckle_link"></parent>
		<child link="robotiq_85_left_finger_tip_link"></child>
		<axis xyz="0 -1 0"></axis>
	</joint>
	<joint name="robotiq_85_right_inner_knuckle_joint" type="fixed">
		<origin xyz="-0.0126999999998499 0 0.0693075000000361" rpy="0 0 3.14159265358979"></origin>
		<parent link="robotiq_85_base_link"></parent>
		<child link="robotiq_85_right_inner_knuckle_link"></child>
		<axis xyz="0 1 0"></axis>
	</joint>
	<joint name="robotiq_85_right_finger_tip_joint" type="fixed">
		<origin xyz="0.0341060475457406 0 0.0458573878541688" rpy="0 0 0"></origin>
		<parent link="robotiq_85_right_inner_knuckle_link"></parent>
		<child link="robotiq_85_right_finger_tip_link"></child>
		<axis xyz="0 1 0"></axis>
	</joint>
	<joint name="robotiq_85_right_knuckle_joint" type="fixed">
		<origin xyz="-0.0306011444258893 0 0.0627920162695395" rpy="0 0 3.14159265358979"></origin>
		<parent link="robotiq_85_base_link"></parent>
		<child link="robotiq_85_right_knuckle_link"></child>
		<axis xyz="0 1 0"></axis>
	</joint>
	<joint name="robotiq_85_right_finger_joint" type="fixed">
		<origin xyz="0.0317095909367246 0 -0.0016013564954687" rpy="0 0 0"></origin>
		<parent link="robotiq_85_right_knuckle_link"></parent>
		<child link="robotiq_85_right_finger_link"></child>
		<axis xyz="0 1 0"></axis>
	</joint>
</robot>
